Workbook
Name ALAMBRE: 'MATERIALES '!$B$29
Name AMARILLA: 'MATERIALES '!$G$11
Name AYUDANTE: 'MATERIALES '!$B$43
Name BLANCA: 'MATERIALES '!$G$12
Name bloc1450: 'MATERIALES '!$G$57
Name BLOCK1425: 'MATERIALES '!$G$45
Name BLOCK1435: 'MATERIALES '!$G$54
Name BLOCK1925: 'MATERIALES '!$G$46
Name BLOCK1935: 'MATERIALES '!$G$55
Name block1950: 'MATERIALES '!$G$58
Name BLOCK925: 'MATERIALES '!$G$44
Name BLOCK935: 'MATERIALES '!$G$53
Name BLOCKU1425: 'MATERIALES '!$G$47
Name BLOCKU1435: 'MATERIALES '!$G$49
Name BLOCKU1925: 'MATERIALES '!$G$48
Name BLOCKU1935: 'MATERIALES '!$G$50
Name blocU1450: 'MATERIALES '!$G$51
Name blocU1950: 'MATERIALES '!$G$52
Name CAL: 'MATERIALES '!$G$13
Name CEMENTO: 'MATERIALES '!$G$8
Name CLAVO: 'MATERIALES '!$B$30
Name flete1450: 'MATERIALES '!$H$57
Name flete1925: 'MATERIALES '!$H$46
Name flete1950: 'MATERIALES '!$H$58
Name FLETE2C: 'MATERIALES '!$C$8
Name FLETE2P: 'MATERIALES '!$D$8
Name FLETE3C: 'MATERIALES '!$C$9
Name FLETE3P: 'MATERIALES '!$D$9
Name FLETE4C: 'MATERIALES '!$C$10
Name FLETE4P: 'MATERIALES '!$D$10
Name FLETE5C: 'MATERIALES '!$C$11
Name FLETE5P: 'MATERIALES '!$D$11
Name FLETE6C: 'MATERIALES '!$C$12
Name FLETE7C: 'MATERIALES '!$C$13
Name FLETE8C: 'MATERIALES '!$C$14
Name fleteU1450: 'MATERIALES '!$H$51
Name fleteU1950: 'MATERIALES '!$H$52
Name HIERRO1040: 'MATERIALES '!$B$16
Name HIERRO1140: 'MATERIALES '!$B$17
Name HIERRO240: 'MATERIALES '!$B$8
Name HIERRO340: 'MATERIALES '!$B$9
Name HIERRO440: 'MATERIALES '!$B$10
Name HIERRO540: 'MATERIALES '!$B$11
Name HIERRO640: 'MATERIALES '!$B$23
Name HIERRO6400: 'MATERIALES '!$B$12
Name HIERRO660: 'MATERIALES '!$B$23
Name HIERRO740: 'MATERIALES '!$B$13
Name HIERRO840: 'MATERIALES '!$B$14
Name HIERRO940: 'MATERIALES '!$B$15
Name INDIRECTOS: 'MATERIALES '!$B$45
Name MADERA: 'MATERIALES '!$G$19
Name PIEDRIN: 'MATERIALES '!$G$10
Name PRESTACIONES: 'MATERIALES '!$B$44
Name RIO: 'MATERIALES '!$G$9
Name SELECTO: 'MATERIALES '!$G$20

Sheet MATERIALES 
A2: MATERIALES PARA PROYECTO EN HUEHUETANGO | F2: Distancia en Kms. | G2: 125
B3: Flete en Camion 200 qq | D3: 500 | F3: Flete en plataforma 560 qq | G3: 500
A6: MATERIAL | B6: C. UNITARIO | C6: CAMION | D6: PLATAFORMA | F6: MATERIAL | G6: C. UNITARIO | H6: CAMION | I6: PLATAFORMA
A7: Hierro grado 40 | B7: 385 | C7: =+G2*14 -> 1750 | D7: 4200 | E7: No. VR/qq
A8: Hierro No. 2 | B8: =+B7/E8 -> 13.099694 | C8: =+(C7/200)/E8 -> 0.29772031 | D8: 0.2559727 | E8: 29.39 | F8: Cemento ugc | G8: 78
A9: Hierro No. 3 | B9: =+B7/E9 -> 28.947368 | C9: =+(C7/200)/E9 -> 0.65789474 | D9: 6.3157895 | E9: 13.3 | F9: Arena de rio | G9: 110
A10: Hierro No. 4 | B10: =+B7/E10 -> 51.401869 | C10: =+(C7/200)/E10 -> 1.1682243 | D10: 1.0053619 | E10: 7.49 | F10: Piedrin | G10: 195
A11: Hierro No. 5 | B11: =+B7/E11 -> 80.375783 | C11: =+(C7/200)/E11 -> 1.8267223 | D11: 1.565762 | E11: 4.79 | F11: Arena amarilla | G11: 90
A12: Hierro No. 6 | B12: =+B7/E12 -> 115.61562 | C12: =+(C7/200)/E12 -> 2.6276276 | D12: 2.2522523 | E12: 3.33 | F12: Arena blanca | G12: 90
A13: Hierro No. 7 | B13: =+B7/E13 -> 157.14286 | C13: =+(C7/200)/E13 -> 3.5714286 | D13: 3.0612245 | E13: 2.45 | F13: Cal horcalsa | G13: 27
A14: Hierro No. 8 | B14: =+B7/E14 -> 205.88235 | C14: =+(C7/200)/E14 -> 4.6791444 | D14: 4.2134831 | E14: 1.87 | F14: Pegasso base | G14: 45
A15: Hierro No. 9 | B15: =+B7/E15 -> 260.13514 | C15: =+(C7/200)/E15 -> 5.9121622 | D15: 5.0675676 | E15: 1.48 | F15: Pegasso fino | G15: 42
A16: Hierro No. 10 | B16: =+B7/E16 -> 320.83333 | C16: 2.5 | D16: 6.25 | E16: 1.2 | F16: Pegasso extrafino | G16: 43
A17: Hierro No. 11 | B17: =+B7/E17 -> 388.88889 | C17: 3.030303 | D17: 7.5757576 | E17: 0.99 | F17: Pegamix | G17: 35
A18: Hierro grado 60 | B18: 316 | C18: 2600 | D18: 4200 | F18: Boquillex | G18: 32
A19: Hierro No. 2 | B19: 10.784983 | C19: 0.44368601 | D19: 0.24714605 | F19: Madera pino rustico | G19: 6
A20: Hierro No. 3 | B20: 23.759398 | C20: 0.97744361 | D20: 0.54446461 | F20: Selecto | G20: 60
A21: Hierro No. 4 | B21: 42.189586 | C21: 1.7426273 | D21: 0.97069428
A22: Hierro No. 5 | B22: 65.970772 | C22: 2.7139875 | D22: 1.5117702 | F22: Concreto 3,000 psi, piedrin 3/4 | G22: 1025
A23: Hierro No. 6 | B23: 94.894895 | C23: 3.9039039 | D23: 2.1745884 | F23: Concreto 4,000 psi, piedrin 3/4 | G23: 1140
A24: Hierro No. 7 | B24: 128.97959 | C24: 5.3061224 | D24: 2.955665 | F24: Concreto 5,000 psi, piedrin 3/4 | G24: 1230
A25: Hierro No. 8 | B25: 168.98396 | C25: 7.3033708 | D25: 4.2134831 | F25: Servicio de bombeo de concreto | G25: 200
A26: Hierro No. 9 | B26: 213.51351 | C26: 8.7837838 | D26: 5.0675676
A27: Hierro No. 10 | B27: 263.33333 | C27: 10.833333 | D27: 6.25
A28: Hierro No. 11 | B28: 319.19192 | C28: 13.131313 | D28: 7.5757576
A29: Alambre de amarre | B29: 5.5
A30: Clavo | B30: 5.5
A31: Electromalla 2/2 | B31: 581.35
A32: Electromalla 3/3 | B32: 502
A33: Electromalla 4/4 | B33: 427.25
A34: Electromalla 5/5 | B34: 395.04
A35: Electromalla 6/6 | B35: 311
A36: Electromalla 7/7 | B36: 264.4
A37: Electromalla 8/8 | B37: 221.65
A38: Electromalla 9/9 | B38: 185.6
A39: Electromalla 10/10 | B39: 153.6
A42: GASTOS ADMINISTRATIVOS | H42: 3900
A43: Ayudantes de albañil | B43: 40 | H43: CAMION | I43: PLATAFORMA
A44: Prestaciones | B44: 40 | F44: Block 0.09x0.19x0.39x25 kgs | G44: 2 | H44: =+H42/1500 -> 2.6
A45: Factor de indirectos | B45: 0.4 | F45: Block 0.14x0.19x0.39x25 kgs | G45: 2.55 | H45: =+H42/1100 -> 3.5454545
...

Sheet CU.
A1: CUADRO DE COSTOS UNITARIOS
A3: RENGLON: | B3: 1 | C3: UNIDAD DE COSTO EXPRESADO EN: | D3: M2 | E3: OBRA: | F3: CASA RUDY MAEDA
A4: CONCEPTO: | B4: LIMPIEZA, CHAPEO Y DESTRONQUE | C4: CANTIDAD: | D4: 96 | E4: LOCALIZACION: | F4: ALDEA EL TULE
A5: CLAVE: | B5: 1.1 | E5: FECHA: | F5: 42436
A7: DESCRIPCION | C7: CANTIDAD | D7: UNIDAD | E7: COSTO UNITARIO | F7: COSTO DIRECTO
A8: MATERIALES
F9: =+TRUNC(ROUND(E9*C9,2),2) -> 0
F10: =+TRUNC(ROUND(E10*C10,2),2) -> 0
F11: =+TRUNC(ROUND(E11*C11,2),2) -> 0
F12: =+TRUNC(ROUND(E12*C12,2),2) -> 0
F13: =+TRUNC(ROUND(E13*C13,2),2) -> 0
F14: =+TRUNC(ROUND(E14*C14,2),2) -> 0
F15: =+TRUNC(ROUND(E15*C15,2),2) -> 0
F16: =+TRUNC(ROUND(E16*C16,2),2) -> 0
B17: TOTAL DE MATERIALES | F17: =SUM(F9:F16) -> 0
A18: MANO DE OBRA
A19: Limpieza , chapeo, y destronque | C19: =+D4 -> 96 | D19: m2 | E19: 10 | F19: =+TRUNC(ROUND(E19*C19,2),2) -> 960
F20: =+TRUNC(ROUND(E20*C20,2),2) -> 0
F21: =+TRUNC(ROUND(E21*C21,2),2) -> 0
F22: =+TRUNC(ROUND(E22*C22,2),2) -> 0
F23: =+TRUNC(ROUND(E23*C23,2),2) -> 0
F24: =+TRUNC(ROUND(E24*C24,2),2) -> 0
C25: SUBTOTAL MANO DE OBRA | F25: =SUM(F19:F24) -> 960
B26: AYUDANTE | C26: =+AYUDANTE -> 40 | D26: % | F26: =+TRUNC(ROUND(E26*C26,2),2)/100 -> 0
B27: PRESTACIONES | C27: =+PRESTACIONES -> 40 | D27: % | F27: =+TRUNC(ROUND(E27*C27,2),2)/100 -> 0
B28: TOTAL DE MANO DE OBRA | F28: =+F27+F26+F25 -> 960
D29: COSTO DIRECTO TOTAL | F29: =+F28+F17 -> 960 | G29: =+F29 -> 960 | H29: =+F17+F28+F31 -> 964
D30: COSTO UNITARIO DIRECTO | F30: =+TRUNC(ROUND(F29/D4,2),2) -> 10
D31: COSTO UNITARIO INDIRECTO | F31: =+F30*INDIRECTOS -> 4
D32: COSTO UNITARIO TOTAL | F32: =+F31+F30 -> 14
A34: RENGLON: | B34: =+B3 -> 1 | C34: UNIDAD DE COSTO EXPRESADO EN: | D34: ML | E34: OBRA: | F34: =F3 -> CASA RUDY MAEDA
A35: CONCEPTO: | B35: TRAZO Y ESTAQUEADO | C35: CANTIDAD: | D35: 68.98 | E35: LOCALIZACION: | F35: =F4 -> ALDEA EL TULE
A36: CLAVE: | B36: 1.2 | E36: FECHA: | F36: =+F5 -> 42436
A38: DESCRIPCION | C38: CANTIDAD | D38: UNIDAD | E38: COSTO UNITARIO | F38: COSTO DIRECTO
A39: MATERIALES
A40: cal | C40: 1 | D40: bolsa | E40: =+CAL -> 27 | F40: =+TRUNC(ROUND(E40*C40,2),2) -> 27
A41: Madera | C41: =+D35*24*1/12 -> 137.96 | D41: p.t. | E41: =+MADERA -> 6 | F41: =+TRUNC(ROUND(E41*C41,2),2) -> 827.76
A42: clavo | C42: =+C41*0.03 -> 4.1388 | D42: libra | E42: 5 | F42: =+TRUNC(ROUND(E42*C42,2),2) -> 20.69
F43: =+TRUNC(ROUND(E43*C43,2),2) -> 0
F44: =+TRUNC(ROUND(E44*C44,2),2) -> 0
...

Sheet MATERIALES
A1: DESCRIPCION | B1: CANTIDAD | C1: UNIDAD | D1: COSTO MATERIALES | E1: TOTAL
A3: CAL | B3: 1 | C3: SACO | D3: 27 | E3: =B3*D3 -> 27
A4: CEMENTO | B4: =+CU.!C71+CU.!C104+CU.!C137+CU.!C168+CU.!C199+CU.!C231+CU.!C261+CU.!C294+CU.!C327+CU.!C359+CU.!C392+CU.!C424+CU.!C456+CU.!C521+CU.!C811 -> 148.79162 | C4: SACO | D4: 72 | E4: =D4*B4 -> 10712.996
A5: ARENA | B5: =+CU.!C72+CU.!C105+CU.!C138+CU.!C169+CU.!C200+CU.!C232+CU.!C262+CU.!C295+CU.!C328+CU.!C360+CU.!C393+CU.!C425+CU.!C457+CU.!C522 -> 11.926448 | C5: M3 | D5: 90 | E5: =D5*B5 -> 1073.3803
A6: PIEDRIN | B6: =+CU.!C73+CU.!C106+CU.!C263+CU.!C296+CU.!C329+CU.!C361+CU.!C394+CU.!C426+CU.!C458+CU.!C523 -> 8.2276322 | C6: M3 | D6: 180 | E6: =D6*B6 -> 1480.9738
A7: BLOCK 0.14*0.19*0.39 | B7: =+CU.!C136+CU.!C167+CU.!C230 -> 1793.272 | C7: UNIDAD | D7: 3.65 | E7: =D7*B7 -> 6545.4428
A8: BLOCK U 0.14*0.19*0.39 | B8: =CU.!C293 -> 108.3 | C8: UNIDAD | D8: 3.65 | E8: =D8*B8 -> 395.295
A9: BLOCK 0.09 *0.19*0.39 | B9: =CU.!C198 -> 847.34 | C9: UNIDAD | D9: 3.65 | E9: =D9*B9 -> 3092.791
A10: HIERRO 3/8 | B10: =+CU.!C74+CU.!C107+CU.!C264+CU.!C297+CU.!C330+CU.!C362+CU.!C395+CU.!C427+CU.!C459+CU.!C524 -> 283.11083 | C10: VARILLA | D10: 11.15 | E10: =D10*B10 -> 3156.6858
A11: HIERRO 1/4 | B11: =CU.!C75+CU.!C265+CU.!C298+CU.!C331+CU.!C363+CU.!C396+CU.!C428+CU.!C460+CU.!C525 -> 154.93894 | C11: VARILLA | D11: 5.16 | E11: =D11*B11 -> 799.48495
A12: CLAVOS | B12: =+CU.!C42+CU.!C76+CU.!C266 -> 35.2628 | C12: LB | D12: 5.25 | E12: =D12*B12 -> 185.1297
A13: ALAMBRE | B13: =+CU.!C77+CU.!C110+CU.!C267+CU.!C300+CU.!C333+CU.!C365+CU.!C398+CU.!C430+CU.!C462+CU.!C527 -> 94.298358 | C13: LB | D13: 4.5 | E13: =D13*B13 -> 424.34261
A14: MADERA | B14: =+CU.!C41+CU.!C78+CU.!C268 -> 1175.4267 | C14: PT | D14: 6 | E14: =D14*B14 -> 7052.56
A15: PISO DE GRANITO | B15: =CU.!C810 -> 65.95 | C15: M2 | D15: 70 | E15: =D15*B15 -> 4616.5
A16: ASULEJO 0.20 * 0.30 | B16: =CU.!C842 -> 18 | C16: M2 | D16: 70 | E16: =D16*B16 -> 1260
A17: LAMINA ACANALADA CAL. 28 6` | B17: =CU.!C489 -> 40 | C17: UNIDAD | D17: 51 | E17: =D17*B17 -> 2040
A18: COSTANERAS COMERCIALES 2" X 4" | B18: =CU.!C491 -> 28 | C18: UNIDAD | D18: 90 | E18: =D18*B18 -> 2520
B19: TOTAL | E19: =SUM(E3:E18) -> 45382.582

Sheet PRE
B2: PRESUPUESTO CASA FAMILIA SALAZAR | J2: 42536
B3: RENGLON | C3: DESCRIPCION | D3: CANTIDAD | E3: UNIDAD | F3: MANO | G3: MATERIALES | H3: TOTAL | I3: TOTAL DEL | J3: COSTO
F4: DE OBRA | I4: RENGLÓN | J4: UNITARIO
B5: =+CU.!B3 -> 1 | C5: TRABAJOS PRELIMINARES | I5: =SUM(H6:H7) -> 2628.72
B6: =+CU.!B5 -> 1.1 | C6: =+CU.!B4 -> LIMPIEZA, CHAPEO Y DESTRONQUE | D6: =+CU.!D4 -> 96 | E6: =+CU.!D3 -> M2 | F6: =+CU.!F28 -> 960 | G6: =+CU.!F17 -> 0 | H6: =+F6+G6 -> 960 | J6: =+CU.!F32 -> 14
B7: =+CU.!B36 -> 1.2 | C7: =+CU.!B35 -> TRAZO Y ESTAQUEADO | D7: =+CU.!D35 -> 68.98 | E7: =+CU.!D34 -> ML | F7: =+CU.!F59 -> 793.27 | G7: =+CU.!F48 -> 875.45 | H7: =+F7+G7 -> 1668.72 | J7: =+CU.!F63 -> 33.866
B8: =CU.!B65 -> 2 | C8: CIMENTACION | I8: =SUM(H9:H10) -> 9573.89
B9: =+CU.!B67 -> 2.1 | C9: =+CU.!B66 -> CIMIENTO CORRIDO RECTANGULAR CC-01 DE 0.20 X 0.40 | D9: =+CU.!D66 -> 68.98 | E9: =+CU.!D65 -> ML | F9: =+CU.!F91 -> 1334.76 | G9: =+CU.!F80 -> 6648 | H9: =+F9+G9 -> 7982.76 | J9: =+CU.!F95 -> 162.022
B10: =+CU.!B100 -> 2.2 | C10: =+CU.!B99 -> ZAPATAS | D10: =+CU.!D99 -> 13 | E10: =+CU.!D98 -> UNIDAD | F10: =+CU.!F124 -> 434.15 | G10: =+CU.!F113 -> 1156.98 | H10: =+F10+G10 -> 1591.13 | J10: =+CU.!F128 -> 171.346
B11: =+CU.!B130 -> 3 | C11: LEVANTADO DE BLOCK | I11: =SUM(H12:H14) -> 13207.6
B12: =+CU.!B132 -> 3.1 | C12: =+CU.!B131 -> LEVANTADO DE BLOCK HASTA SOLERA HIDROFUGA | D12: =+CU.!D131 -> 55.184 | E12: =+CU.!D130 -> M2 | F12: =+CU.!F155 -> 1545.15 | G12: =+CU.!F144 -> 2419.72 | H12: =+F12+G12 -> 3964.87 | J12: =+CU.!F159 -> 100.59
B13: =+CU.!B163 -> 3.2 | C13: =+CU.!B162 -> LEVANTADO DE BLOCK 0.14 X 0.19 X 0.39 DE 50 KG. CISADO UNA CARA | D13: =+CU.!D162 -> 53.35 | E13: =+CU.!D161 -> M2 | F13: =+CU.!F186 -> 1867.25 | G13: =+CU.!F175 -> 2339.31 | H13: =+F13+G13 -> 4206.56 | J13: =+CU.!F190 -> 110.39
B14: =+CU.!B194 -> 3.3 | C14: =+CU.!B193 -> LEVANTADO DE BLOCK 0.09 X 0.19 X 0.39 | D14: =+CU.!D193 -> 65.18 | E14: =+CU.!D192 -> M2 | F14: =+CU.!F217 -> 2933.1 | G14: =+CU.!F206 -> 2103.07 | H14: =+F14+G14 -> 5036.17 | J14: =+CU.!F221 -> 108.178
B15: =+CU.!B255 -> 4 | C15: SOLERAS | I15: =SUM(H16:H19) -> 13144.15
B16: =+CU.!B257 -> 4.1 | C16: =+CU.!B256 -> SOLERA HIDROFUGA Y MOJINETE DE 0.14 X 0.20 | D16: =+CU.!D256 -> 121.13 | E16: =+CU.!D255 -> ML | F16: =+CU.!F281 -> 1492.32 | G16: =+CU.!F270 -> 9754.39 | H16: =+F16+G16 -> 11246.71 | J16: =+CU.!F285 -> 129.99
B17: =+CU.!B289 -> 4.2 | C17: =+CU.!B288 -> SOLERA INTERMEDIA DE BLOCK U | D17: =+CU.!D288 -> 36.1 | E17: =+CU.!D287 -> ML | F17: =+CU.!F314 -> 111.19 | G17: =+CU.!F303 -> 344.89 | H17: =+F17+G17 -> 456.08 | J17: =+CU.!F318 -> 17.682
B18: =+CU.!B323 -> 4.3 | C18: =+CU.!B322 -> SILLAR DE 0.10 X 0.14 | D18: =+CU.!D322 -> 9.6 | E18: =+CU.!D321 -> ML | F18: =+CU.!F347 -> 478.27 | G18: =+CU.!F336 -> 249.8 | H18: =+F18+G18 -> 728.07 | J18: =+CU.!F351 -> 106.176
B19: =+CU.!B355 -> 4.4 | C19: =+CU.!B354 -> DINTEL DE 0.10 X 0.14 | D19: =+CU.!D354 -> 9.6 | E19: =+CU.!D353 -> ML | F19: =+CU.!F379 -> 463.49 | G19: =+CU.!F368 -> 249.8 | H19: =+F19+G19 -> 713.29 | J19: =+CU.!F383 -> 104.02
B20: =+CU.!B386 -> 5 | C20: COLUMNAS | I20: =SUM(H21:H23) -> 21484.02
B21: =+CU.!B388 -> 5.1 | C21: =+CU.!B387 -> COLUMNAS TIPO C-1 DE 0.20 X 0.15 | D21: =+CU.!D387 -> 39 | E21: =+CU.!D386 -> ML | F21: =+CU.!F412 -> 3786.12 | G21: =+CU.!F401 -> 1565.78 | H21: =+F21+G21 -> 5351.9 | J21: =+CU.!F416 -> 192.122
B22: =+CU.!B420 -> 5.2 | C22: =+CU.!B419 -> COLUMNAS TIPO C-2 DE 0.15 X 0.15 | D22: =+CU.!D419 -> 36 | E22: =+CU.!D418 -> ML | F22: =+CU.!F444 -> 3306.36 | G22: =+CU.!F433 -> 8216.08 | H22: =+F22+G22 -> 11522.44 | J22: =+CU.!F448 -> 448.098
B23: =+CU.!B452 -> 5.3 | C23: =+CU.!B451 -> COLUMNAS TIPO C-3 DE 0.10 X 0.15 | D23: =+CU.!D451 -> 40 | E23: =+CU.!D450 -> ML | F23: =+CU.!F476 -> 3626.93 | G23: =+CU.!F465 -> 982.75 | H23: =+F23+G23 -> 4609.68 | J23: =+CU.!F480 -> 161.336
B24: =+CU.!B483 -> 6 | C24: LOSAS | I24: =SUM(H25:H25) -> 8152
B25: =+CU.!B485 -> 6.1 | C25: =+CU.!B484 -> TECHO ESTRUCTURA METALICA | D25: =+CU.!D484 -> 91.25 | E25: =+CU.!D483 -> M2 | F25: =+CU.!F508 -> 3000 | G25: =+CU.!F497 -> 5152 | H25: =+F25+G25 -> 8152 | J25: =+CU.!F512 -> 125.076
B26: =+CU.!B515 -> 7 | C26: INSTALACION ELECTRICA | I26: =SUM(H27:H28) -> 681
B27: =+CU.!B517 -> 7.1 | C27: =+CU.!B516 -> ACOMETIDA ELECTRICA | D27: =+CU.!D516 -> 2.7 | E27: =+CU.!D515 -> ML | F27: =+CU.!F541 -> 253.36 | G27: =+CU.!F530 -> 177.64 | H27: =+F27+G27 -> 431 | J27: =+CU.!F545 -> 223.482
B28: =+CU.!B549 -> 7.2 | C28: =+CU.!B548 -> INSTALACION ELECTRICA | D28: =+CU.!D548 -> 1 | E28: =+CU.!D547 -> GLOBAL | F28: =+CU.!F580 -> 250 | G28: =+CU.!F569 -> 0 | H28: =+F28+G28 -> 250 | J28: =+CU.!F584 -> 350
B29: =+CU.!B586 -> 8 | C29: INSTALACION DE AGUA POTABLE | I29: =+H30 -> 63.5
B30: =+CU.!B588 -> 8.1 | C30: =+CU.!B587 -> INSTALACION DE AGUA POTABLE | D30: =+CU.!D587 -> 1 | E30: =+CU.!D586 -> GLOBAL | F30: =+CU.!F611 -> 63.5 | G30: =+CU.!F600 -> 0 | H30: =+F30+G30 -> 63.5 | J30: =+CU.!F615 -> 88.9
B31: =+CU.!B617 -> 9 | C31: INSTALACION DE DRENAJES | I31: =SUM(H32:H32) -> 63.5
B32: =+CU.!B619 -> 9.1 | C32: =+CU.!B618 -> INSTALACION DE DRENAJE SANITARIO | D32: =+CU.!D618 -> 1 | E32: =+CU.!D617 -> GLOBAL | F32: =+CU.!F642 -> 63.5 | G32: =+CU.!F631 -> 0 | H32: =+F32+G32 -> 63.5 | J32: =+CU.!F646 -> 88.9
B33: =+CU.!B649 -> 10 | C33: ARTEFACTOS | I33: =SUM(H34:H38) -> 817.64
B34: =+CU.!B651 -> 10.1 | C34: =+CU.!B650 -> PILA DE UN LAVADERO | D34: =+CU.!D650 -> 1 | E34: =+CU.!D649 -> UNIDAD | F34: =+CU.!F674 -> 200 | G34: =+CU.!F663 -> 0 | H34: =+F34+G34 -> 200 | J34: =+CU.!F678 -> 280
B35: =+CU.!B682 -> 10.2 | C35: =+CU.!B681 -> LAVAPLATOS DE 1 FOSA | D35: =+CU.!D681 -> 1 | E35: =+CU.!D680 -> UNIDAD | F35: =+CU.!F705 -> 250 | G35: =+CU.!F694 -> 0 | H35: =+F35+G35 -> 250 | J35: =+CU.!F709 -> 350
B36: =+CU.!B713 -> 10.3 | C36: =+CU.!B712 -> INODORO | D36: =+CU.!D712 -> 1 | E36: =+CU.!D711 -> UNIDAD | F36: =+CU.!F736 -> 200 | G36: =+CU.!F725 -> 0 | H36: =+F36+G36 -> 200 | J36: =+CU.!F740 -> 280
B37: =+CU.!B744 -> 10.4 | C37: =+CU.!B743 -> LAVAMANOS | D37: =+CU.!D743 -> 1 | E37: =+CU.!D742 -> UNIDAD | F37: =+CU.!F767 -> 83.82 | G37: =+CU.!F756 -> 0 | H37: =+F37+G37 -> 83.82 | J37: =+CU.!F771 -> 117.348
B38: =+CU.!B775 -> 10.5 | C38: =+CU.!B774 -> DUCHA | D38: =+CU.!D774 -> 1 | E38: =+CU.!D773 -> UNIDAD | F38: =+CU.!F798 -> 83.82 | G38: =+CU.!F787 -> 0 | H38: =+F38+G38 -> 83.82 | J38: =+CU.!F802 -> 117.348
B39: 11 | C39: ACABADOS | I39: =SUM(H40:H43) -> 15506.58
B40: =+CU.!B806 -> 11.1 | C40: =+CU.!B805 -> PISO DE GRNITO | D40: =+CU.!D805 -> 65.95 | E40: =+CU.!D804 -> M2 | F40: =+CU.!F829 -> 1319 | G40: =+CU.!F818 -> 6126 | H40: =+F40+G40 -> 7445 | J40: =+CU.!F833 -> 158.046
B41: =+CU.!B838 -> 11.4 | C41: =+CU.!B837 -> AZULEJO DE 0.20 X 0.30 | D41: =+CU.!D837 -> 18 | E41: =+CU.!D836 -> M2 | F41: =+CU.!F861 -> 360 | G41: =+CU.!F850 -> 1800 | H41: =+F41+G41 -> 2160 | J41: =+CU.!F865 -> 168
...
